### 5.6 점프문

- 이름 그대로 인터프리터가 점프문을 만나면 소스 내 특정 위치로 건너뛴다.

#### 5.6.1 레이블

- 어떤 문장에 식별자 이름과 클론(:)을 넣으므로써 레이블을 붙일 수 있다.
- 레이블을 붙이면 다른 곳에서 문장을 참고 할 수 있어 유용하다.
- 예약어를 제외한 모든 적법한 자바스크립트의 식별자는 레이블이 될 수 있다.
  ```js
  mainloop: while (token != null) {
    //코드 생략
    continue mainloop; //주어진 mainloop의 다음 반복으로 건너뛴다.
    //코드 생략
  }
  ```

#### 5.6.2 break

- break문을 만나면 이를 감싸고 있는 가장 안쪽의 루프 혹은 switch문에서 즉시 빠져나온다.
- break문은 오직 루프나 switch 문 내부에서만 적법하다.

#### 5.6.3 continue

- break 문과 유사하나 루프를 빠져나오지 않고 새로운 반복을 시작한다는 점이 다르다.
- 루프 내부가 아닌 다른 부분에 사용하면 문법 에러가 발생한다.
- while 루프 내부에서 continue문이 실행되면 루프의 시작 부분에 지정된 표현식을 다시 테스트한다.
  결과가 true 이면 루프 몸체 처음부터 다시 실행을 시작한다.
- for 내부에서는 증감 표현식을 평가한 후, 테스트 표현식을 테스트하여 다음 반복을 수행할지 결정한다.

#### 5.6.4 return

- 함수 호출 표현식의 값,즉 함수에서 반환하는 값을 지정하는데 쓰인다.
- return 문은 오직 함수 내부에서만 나타날 수 있고, 다른곳에서 쓰이면 문법 에러가 발생한다.
- return 문이 실행되면 표현식이 평가되어 그 결과가 함수의 값으로 반환된다

  ```js
  return 표현식; //작성방법, 자바스크립트의 자동 세미콜론 삽입 기능 때문에return 과 표현식 사이에 줄바꿈을 하면 안된다.

  function square(x) {
    return x * x;
  } //return 문을 가지고 있는 함수
  square(2); //이 호출은 4로 평가된다
  ```

- 함수 내에 return 문이 없다면 함수 호출은 함수 내부의 구문을 차례로 실행하고 호출한 지점으로 돌아간다.
- 함수 내에 return 문이 없는 경우 해당 함수 호출 표현식의 값은 undefined 가 된다.
- 함수 내부에서 return 문이 실행되면 아직 남은 문장들이 있더라도 함수를 호출한 지점으로 돌아간다.

#### 5.6.5 throw

- 예외를 발생시키는 것(throw)은 에러나 예외상황을 알린다는 의미이고, 이를 잡아내는(catch)는 것은 예외를 처리한다는 것이다.
- 자바스크립트에서는 런타임 에러가 일어날 때마다 예외를 발생시킨다.
- 이러한 예외는 try/catch/finally 문을 사용해 처리할 수 있다.

  ```js
  throw 표현식; //작성방법

  function factorial(x) {
    // 만약 입력 전달인자가 유효하지 않으면 예외를 발생시킨다, 에러객체 발생
    if (x < 0) throw new Error("x must not be negative!");
    // 유효하다면 값을 계산하여 정상적으로 반환한다.
    for (let f = 1; x > 1; f *= x, x--);
  }
  ```

- 표현식은 어떤 자료형의 값으로도 평가될 수 있으므로 숫자/문자열을 던질 수 있다.
- Error 객체는 에러의 종류를 담고있는 name 프로퍼티와 message 프로퍼티를 갖고 있다.
- 예외가 발생할 경우 자바스크립트 인터프리터는 프로그램 실행을 즉시 중단하고 가까운 catch 절로 작성된 예외 처리기로 넘어간다.
  예외처리기를 찾을 수 없다면 해당 예외는 에러로 취급되어 사용자에게 보고된다.

#### 5.6.6 try/catch/finally

- try절은 예외가 발생할지도 모르는 코드 블록을 정의하는 역할을 한다.
- catch 절은 try 절 이후에 오며, try 블록 내부에서 예외가 발생할 경우 호출되는 문장 블록이다.
- finally 절은 catch 절 다음에 오며 try 블록에서 일어난 일에 관계없이 실행된다. 뒷정리용 코드
- catch 나 finally 블록은 생략이 가능하나 try 블록이 사용되었다면 catch/finally 중 하나 이상이 함께 사용되어야 한다.
  ```js
  try {
    //코드생략
  } catch (e) {
    //코드생략
  }
  ```
- 예외가 발생하면 Error 객체와 같이 예외와 관련된 값이 catch 키워드 다음에 오는 괄호 안의 식별자에 할당된다.
- 만일 try 블록에서 예외가 발생했는데 예외처리용 catch 블록이 있다면 catch블록으로 이동한 후에 finally 블록으로 이동한다.
